Workbook

Sheet data
A1: pseudonym | B1: test
A2: date of inclusion
A3: cohort
A4: inclusion criterium
A5: entry done
A6: exclusion due to exclusion criteria
A7: exclusion at patient's request
A8: reason for exclusion
A9: previous CAD diagnostic
A10: CAD previously known
A11: day + time at ED visit (for ED cohort only)
A12: day + time at M61 admission (for ED cohort only)
A13: day + time at admission or discharge (for ED cohort only)
... A21: date of birth
A22: age [years] | B22: =DATEDIF(B21, B2, "Y") -> 0
A23: sex
A24: height [cm]
A25: weight [kg]
A26: BMI [kg/m^2] | B26: =B25/((B24/100)^2) -> #DIV/0!
A27: presence and type of chest pain (CE)
A28: presence and type of chest pain (ESC 2013/ACC 2012)
A29: thoracic pain (ESC 2019)
A30: thoracic pain (ACC 2021)
A31: dyspnoea as shortness of breath and/or trouble catching breath aggravated by physical exertion (ESC 2024)
A32: chest pain type and location (constricting discomfort located retrosternally or in neck, jaw, shoulder or arm) (ESC 2024)
A33: chest pain aggravated by physical or emotional stress (ESC 2024)
A34: chest pain relieved by rest or nitrates within 5 min
A35: nicotine consumption (CE)
A36: nicotine consumption (ESC 2024)
A37: family history
A38: dyslipidemia
... A69: CE (primary care calibration) score
A70: CE (primary care calibration) PTP | B70: =IF(B69="", "error:missing input", IF(B69<=0.71, "<5%", IF(B69<=0.87, "~20%", IF(B69<=0.92, "~50%", IF(B69<=1, ">75%", "error: invalid input"))))) -> error:missing input
A71: CE individual PTP
A72: Diamond-Forrester | B72: {=IF(OR(B117="",B23="",B28=""),"error: missing input",LOOKUP(1,(B117={"age 30-39";"age 30-39";"age 40-49";"age 40-49";"age 50-59";"age 50-59";"age 60-69";"age 60-69";"age 30-39";"age 30-39";"age 40-49";"age 40-49";"age 50-59";"age 50-59";"age 60-69";"age 60-69";"age 30-39";"age 30-39";"age 40-49";"age 40-49";"age 50-59";"age 50-59";"age 60-69";"age 60-69"})*(B28={"typical";"typical";"typical";"typical";"typical";"typical";"typical";"typical";"atypical";"atypical";"atypical";"atypical";"atypical";"atypical";"atypical";"atypical";"nonanginal";"nonanginal";"nonanginal";"nonanginal";"nonanginal";"nonanginal";"nonanginal";"nonanginal"})*(B23={"male";"female";"male";"female";"male";"female";"male";"female";"male";"female";"male";"female";"male";"female";"male";"female";"male";"female";"male";"female";"male";"female";"male";"female"}),{69.7;25.8;87.3;55.2;92;79.4;94.3;90.6;21.8;4.2;46.1;13.3;58.9;32.4;67.1;54.4;5.2;0.8;14.1;2.8;21.5;8.4;28.1;18.6}))} -> error: missing input
A73: CAD consortium score 2012 Basic PTP | B73: =IF(OR(B22="",B23="",B28=""),"error: missing input",1/(1+EXP(-(-6.917+0.063*B22+1.358*IF(B23="male",1,0)+IF(B28="typical",1.975,IF(B28="atypical",0.658,0)))))) -> error: missing input
A74: CAD consortium score 2012 Clinical PTP | B74: =IF(OR(B22="",B23="",B28="",B41="",B39="",B38="",B36=""),"error: missing input",1/(1+EXP(-(-7.539 + 0.062*B22 + 1.332*IF(B23="male",1,0) + IF(B28="typical",1.998,IF(B28="atypical",0.633,0)) + 0.828*IF(B41="yes",1,0) + 0.338*IF(B39="yes",1,0) + 0.422*IF(B38="yes",1,0) + 0.461*IF(B36="yes",1,0) - 0.402*IF(B41="yes",1,0)*IF(B28="typical",1,0))))) -> error: missing input
A75: ACC 2012 PTP | B75: {=IF(OR(B23="", B28="", B117=""), "error: missing input", INDEX(scores!$C$5:$H$8, MATCH(B117, scores!$B$5:$B$8, 0), MATCH(B28, scores!$C$3:$G$3, 0) + IF(B23 = INDEX(scores!$C$4:$G$4, MATCH(B28, scores!$C$3:$G$3, 0)), 0, 1)))} -> error: missing input
A76: ESC 2013 PTP | B76: {=IF(OR(B23="", B28="", B118=""), "error: missing input", INDEX(scores!$K$5:$P$10, MATCH(B118, scores!$J$5:$J$10, 0), MATCH(B28, scores!$K$3:$P$3, 0) + IF(B23 = INDEX(scores!$K$4:$P$4, MATCH(B28, scores!$K$3:$P$3, 0)), 0, 1)))} -> error: missing input
A77: ESC 2019 PTP | B77: {=IF(OR(B23="", B29="", B119=""), "error: missing input", INDEX(scores!$S$5:$Z$9, MATCH(B119, scores!$R$5:$R$9, 0), MATCH(B29, scores!$S$3:$Z$3, 0) + IF(B23 = INDEX(scores!$S$4:$Z$4, MATCH(B28, scores!$S$3:$Z$3, 0)), 0, 1)))} -> error: missing input
...

Sheet dropdown
A1: title | B1: yes/no | C1: cohort | D1: yes/no | E1: no/yes | F1: likelihood for CAD | G1: sex | H1: thoracic pain CE | I1: thoracic pain ESC 2013/ACC 2012 | J1: thoracic pain ESC 2019 | K1: thoracic pain ACC 2021 | L1: nicotine consumption CE | M1: diabetes medication | N1: Q-waves | O1: MACE | P1: non-invasive ischemia testing | Q1: CAD status | R1: inclusion criterium | S1: inpatient admission
A2: options | D2: yes | E2: no | F2: very low | G2: male | H2: no | I2: typical | J2: typical | K2: chest pain | L2: no | M2: no | N2: no | O2: cardiovascular death | P2: stress echocardiography | Q2: inconclusive
B3: yes | C3: DZHI | D3: no | E3: yes | F3: low | G3: female | H3: unspecific | I3: atypical | J3: atypical | K3: dyspnea | L3: status post | M3: NIDDM | N3: yes | O3: non-fatal stroke | P3: myocardial perfusion SPECT | Q3: excluded | R3: Cardio | S3: no
B4: no | C4: ED | F4: moderate | H4: possible | I4: nonanginal | J4: nonanginal | L4: yes | M4: IDDM | N4: no ECG performed | O4: non-fatal myocardial infarction | P4: PET | Q4: diagnosed | R4: HCM | S4: yes
F5: high | H5: typical | J5: dyspnea | O5: need for revascularization or bypass surgery | P5: cardioMRI | R5: HF | S5: ED overnight
F6: very high | O6: no information | P6: none | R6: AF | S6: discharge against medical advice
F7: not assessed | R7: CCS

Sheet scores
B2: ACC 2012 | J2: ESC 2013 | R2: ESC 2019 | AB2: ACC 2021 | AH2: ESC 2024
B3: age | C3: nonanginal | E3: atypical | G3: typical | J3: age | K3: typical | M3: atypical | O3: nonanginal | R3: age | S3: typical | U3: atypical | W3: nonanginal | Y3: dyspnea | AB3: age | AC3: chest pain | AE3: dyspnea | AH3: age \ symptom score, sex, risk factors | AI3: 0-1 | AO3: 2 | AU3: 3 | BB3: ESC 2024 PTP/RF-CL/CACS-CL Scores calculated based on Winther et al., 2020, Table S3, Formulas adapted for Excel | BL3: Diamond-Forrester, CAD2 Score, PROMISE Minimal-Risk Score calculated based on Selva, Jeremy, 2025. pretestcad: Pretest Probability for Coronary Artery Disease. Formulas adapted for Excel https://github.com/JauntyJJS/pretestcad
C4: male | D4: female | E4: male | F4: female | G4: male | H4: female | K4: male | L4: female | M4: male | N4: female | O4: male | P4: female | S4: male | T4: female | U4: male | V4: female | W4: male | X4: female | Y4: male | Z4: female | AC4: male | AD4: female | AE4: male | AF4: female | AI4: female | AL4: male | AO4: female | AR4: male | AU4: female | AX4: male
B5: age 30-39 | C5: 4 | D5: 2 | E5: 34 | F5: 12 | G5: 76 | H5: 26 | J5: age 30-39 | K5: 59 | L5: 28 | M5: 29 | N5: 10 | O5: 18 | P5: 5 | R5: age 30-39 | S5: 3 | T5: 5 | U5: 4 | V5: 3 | W5: 1 | X5: 1 | Y5: 0 | Z5: 3 | AB5: age 30-39 | AC5: 4 | AD5: 5 | AE5: 0 | AF5: 3 | AI5: 0-1 | AJ5: 2-3 | AK5: 4-5 | AL5: 0-1 | AM5: 2-3 | AN5: 4-5 | AO5: 0-1 | AP5: 2-3 | AQ5: 4-5 | AR5: 0-1 | AS5: 2-3 | AT5: 4-5 | AU5: 0-1 | AV5: 2-3 | AW5: 4-5 | AX5: 0-1 | AY5: 2-3 | AZ5: 4-5
B6: age 40-49 | C6: 13 | D6: 3 | E6: 51 | F6: 22 | G6: 87 | H6: 55 | J6: age 40-49 | K6: 69 | L6: 37 | M6: 38 | N6: 14 | O6: 25 | P6: 8 | R6: age 40-49 | S6: 22 | T6: 10 | U6: 10 | V6: 6 | W6: 3 | X6: 2 | Y6: 12 | Z6: 3 | AB6: age 40-49 | AC6: 22 | AD6: 10 | AE6: 12 | AF6: 3 | AH6: age 30-39 | AI6: 0 | AJ6: 1 | AK6: 2 | AL6: 1 | AM6: 2 | AN6: 5 | AO6: 0 | AP6: 1 | AQ6: 3 | AR6: 2 | AS6: 4 | AT6: 8 | AU6: 2 | AV6: 5 | AW6: 10 | AX6: 9 | AY6: 14 | AZ6: 22
B7: age 50-59 | C7: 20 | D7: 7 | E7: 65 | F7: 31 | G7: 93 | H7: 73 | J7: age 50-59 | K7: 77 | L7: 47 | M7: 49 | N7: 20 | O7: 34 | P7: 12 | R7: age 50-59 | S7: 32 | T7: 13 | U7: 17 | V7: 6 | W7: 11 | X7: 3 | Y7: 20 | Z7: 9 | AB7: age 50-59 | AC7: 32 | AD7: 13 | AE7: 20 | AF7: 9 | AH7: age 40-49 | AI7: 1 | AJ7: 1 | AK7: 3 | AL7: 2 | AM7: 4 | AN7: 8 | AO7: 1 | AP7: 2 | AQ7: 5 | AR7: 3 | AS7: 6 | AT7: 12 | AU7: 4 | AV7: 7 | AW7: 12 | AX7: 14 | AY7: 20 | AZ7: 27
B8: age 60-69 | C8: 27 | D8: 14 | E8: 72 | F8: 51 | G8: 94 | H8: 86 | J8: age 60-69 | K8: 84 | L8: 58 | M8: 59 | N8: 28 | O8: 44 | P8: 17 | R8: age 60-69 | S8: 44 | T8: 16 | U8: 26 | V8: 11 | W8: 22 | X8: 6 | Y8: 27 | Z8: 14 | AB8: age 60-69 | AC8: 44 | AD8: 16 | AE8: 27 | AF8: 14 | AH8: age 50-59 | AI8: 1 | AJ8: 2 | AK8: 5 | AL8: 4 | AM8: 7 | AN8: 12 | AO8: 2 | AP8: 3 | AQ8: 7 | AR8: 6 | AS8: 11 | AT8: 17 | AU8: 6 | AV8: 10 | AW8: 15 | AX8: 21 | AY8: 27 | AZ8: 33
J9: age 70-79 | K9: 89 | L9: 68 | M9: 69 | N9: 37 | O9: 54 | P9: 24 | R9: age 70+ | S9: 52 | T9: 27 | U9: 34 | V9: 19 | W9: 24 | X9: 10 | Y9: 32 | Z9: 12 | AB9: age 70+ | AC9: 52 | AD9: 27 | AE9: 32 | AF9: 12 | AH9: age 60-69 | AI9: 2 | AJ9: 4 | AK9: 7 | AL9: 8 | AM9: 12 | AN9: 17 | AO9: 3 | AP9: 6 | AQ9: 11 | AR9: 12 | AS9: 17 | AT9: 25 | AU9: 10 | AV9: 14 | AW9: 19 | AX9: 32 | AY9: 35 | AZ9: 39
J10: age 80+ | K10: 93 | L10: 76 | M10: 78 | N10: 47 | O10: 65 | P10: 32 | AH10: age 70-80 | AI10: 4 | AJ10: 7 | AK10: 11 | AL10: 15 | AM10: 19 | AN10: 24 | AO10: 6 | AP10: 10 | AQ10: 16 | AR10: 22 | AS10: 27 | AT10: 34 | AU10: 16 | AV10: 19 | AW10: 23 | AX10: 44 | AY10: 44 | AZ10: 45
B14: Table 9. Pretest Likelihood of CAD in Symptomatic Patients According to Age and Sex* (Combined Diamond/Forrester and CASS Data) | J14: Table 13, https://doi.org/10.1093/eurheartj/eht296 | R14: Table 5, 10.1093/eurheartj/ehz425 | AB14: Figure 11, 10.1161/CIR.0000000000001029 | AH14: Figure 4, 10.1093/eurheartj/ehae177
